Workbook

Sheet Resumo
A1: JUSFY — DRE contábil × gerencial · Janeiro a Junho 2026
A2: Três degraus, por mês: (1) como está hoje; (2) depois dos 138 lançamentos da Syhus (aba O QUE FAZER) — a única nota explicativa é a competência 2025, que fica em 2026 porque o exercício de 2025 já fechou; (3) depois das pendências que dependem de resposta da Jusfy (aba Notas e pendências). Meta: até 0,5%.
A4: CUSTO (contas 6.2)
B5: Jan | C5: Fev | D5: Mar | E5: Abr | F5: Mai | G5: Jun | H5: Total
A6: Gerencial (P&L oficial) | B6: 1021126.4 | C6: 1037755.6 | D6: 1158496.6 | E6: 1231075.9 | F6: 1323802.1 | G6: 1473722.3 | H6: 7245978.9
A7: Razão como está hoje | B7: 1478048.7 | C7: 801849.28 | D7: 919365.25 | E7: 1057146.9 | F7: 779107.5 | G7: 1239333.6 | H7: 6274851.2
A8: (−) Competência 2025 lançada em 2026 — NOTA EXPLICATIVA (exercício encerrado, fica em 2026) | B8: 618680.1 | C8: 11002.1 | D8: 26786.67 | E8: 0 | F8: -18576.33 | G8: 0 | H8: 637892.54
A9: 1) Diferença HOJE | B9: -161757.86 | C9: -246908.42 | D9: -265918.04 | E9: -173928.99 | F9: -526118.28 | G9: -234388.71 | H9: -1609020.3
A10: % sobre o gerencial | B10: -0.1584112 | C10: -0.2379254 | D10: -0.22953717 | E10: -0.1412821 | F10: -0.3974297 | G10: -0.15904537 | H10: -0.22205699
A11: (+) Lançamentos da Syhus (aba O QUE FAZER) | B11: 150401.43 | C11: 242692.39 | D11: 286844.54 | E11: 171009.44 | F11: 532804.28 | G11: 233640.04 | H11: 1617392.1
A12: 2) Diferença DEPOIS DA SYHUS | B12: -11356.43 | C12: -4216.03 | D12: 20926.5 | E12: -2919.55 | F12: 6686 | G12: -748.67 | H12: 8371.82
A13: % sobre o gerencial | B13: -0.011121473 | C13: -0.0040626425 | D13: 0.018063497 | E13: -0.0023715435 | F13: 0.0050506038 | G13: -0.00050801295 | H13: 0.0011553746
A14: (−) Google Ads: razão = base da Mari (ERP); o P&L está diferente — ajustar o P&L | B14: 0 | C14: 0 | D14: 0 | E14: 0 | F14: 0 | G14: 0 | H14: 0
A15: (−) NF que não está na base da Mari — tesouraria valida (aba Validar Tesouraria) | B15: 0 | C15: 493.83 | D15: 17878.21 | E15: 4756.07 | F15: 4879.32 | G15: 0 | H15: 28007.43
A16: (−) Lançamento sem nº de NF e fora do ERP — pedir a nota à Syhus (aba Pedir NF à Syhus) | B16: 0 | C16: 53.97 | D16: 0 | E16: 0 | F16: 0 | G16: 0 | H16: 53.97
A17: (−) Imposto retido: razão pelo valor bruto da NF, ERP/P&L pelo líquido pago | B17: 0 | C17: 730 | D17: 1628 | E17: 2835 | F17: 2976 | G17: 2447 | H17: 10616
... A24: % sobre o gerencial | B24: -0.0038732422 | C24: -0.0049675087 | D24: -0.0008173783 | E24: -0.0045282505 | F24: -0.0032567859 | G24: -0.0021000497 | H24: -0.0031794062
A26: DESPESA (contas 4.1)
B27: Jan | C27: Fev | D27: Mar | E27: Abr | F27: Mai | G27: Jun | H27: Total
A28: Gerencial (P&L oficial) | B28: 2029394.9 | C28: 1891722.3 | D28: 2172723.6 | E28: 2485367.1 | F28: 3050632.3 | G28: 3065504.4 | H28: 14695345
A29: Razão como está hoje | B29: 2452976.2 | C29: 2305424.9 | D29: 2250602.1 | E29: 2740110.4 | F29: 3273376.2 | G29: 3122469.3 | H29: 16144959
A30: (−) Competência 2025 lançada em 2026 — NOTA EXPLICATIVA (exercício encerrado, fica em 2026) | B30: 481163.62 | C30: 110748.25 | D30: 14335 | E30: 0 | F30: -27403.81 | G30: 0 | H30: 578843.06
A31: 1) Diferença HOJE | B31: -57582.29 | C31: 302954.34 | D31: 63543.5 | E31: 254743.3 | F31: 250147.7 | G31: 56964.9 | H31: 870771.45
A32: % sobre o gerencial | B32: -0.028374119 | C32: 0.16014736 | D32: 0.029246012 | E32: 0.10249725 | F32: 0.08199864 | G32: 0.018582554 | H32: 0.059254919
A33: (+) Lançamentos da Syhus (aba O QUE FAZER) | B33: 24409.44 | C33: -243782.41 | D33: -40690.82 | E33: -236170.79 | F33: -270171.26 | G33: -9026.75 | H33: -775432.59
A34: 2) Diferença DEPOIS DA SYHUS | B34: -33172.85 | C34: 59171.93 | D34: 22852.68 | E34: 18572.51 | F34: -20023.56 | G34: 47938.15 | H34: 95338.86
A35: % sobre o gerencial | B35: -0.016346178 | C35: 0.031279395 | D35: 0.010517988 | E35: 0.0074727432 | F35: -0.0065637409 | G35: 0.015637932 | H35: 0.0064876914
A36: (−) Google Ads: razão = base da Mari (ERP); o P&L está diferente — ajustar o P&L | B36: 6158.49 | C36: 0 | D36: 20003.17 | E36: 12688.86 | F36: 0 | G36: 5034.06 | H36: 43884.58
A37: (−) NF que não está na base da Mari — tesouraria valida (aba Validar Tesouraria) | B37: 22298.56 | C37: 6467.02 | D37: 5127.79 | E37: 2183 | F37: 31609.24 | G37: 4730.43 | H37: 72416.04
A38: (−) Lançamento sem nº de NF e fora do ERP — pedir a nota à Syhus (aba Pedir NF à Syhus) | B38: 267 | C38: 2741.04 | D38: 0 | E38: 0 | F38: 0 | G38: 110.26 | H38: 3118.3
A39: (−) Imposto retido: razão pelo valor bruto da NF, ERP/P&L pelo líquido pago | B39: 149 | C39: 149 | D39: 149.01 | E39: 393.23 | F39: 0 | G39: 660.36 | H39: 1500.6
... A46: % sobre o gerencial | B46: -0.0049685008 | C46: -0.0016715191 | D46: -0.0032766616 | E46: -0.0046960668 | F46: -0.0028910892 | G46: -0.0049087648 | H46: -0.0038041517
A48: TOTAL (custo + despesa)
B49: Jan | C49: Fev | D49: Mar | E49: Abr | F49: Mai | G49: Jun | H49: Total
A50: Gerencial (P&L oficial) | B50: 3050521.3 | C50: 2929477.9 | D50: 3331220.2 | E50: 3716443 | F50: 4374434.4 | G50: 4539226.7 | H50: 21941323
A51: Razão como está hoje | B51: 3931024.9 | C51: 3107274.2 | D51: 3169967.3 | E51: 3797257.3 | F51: 4052483.7 | G51: 4361802.9 | H51: 22419810
A52: (−) Competência 2025 lançada em 2026 — NOTA EXPLICATIVA (exercício encerrado, fica em 2026) | B52: 1099843.7 | C52: 121750.35 | D52: 41121.67 | E52: 0 | F52: -45980.14 | G52: 0 | H52: 1216735.6
A53: 1) Diferença HOJE | B53: -219340.15 | C53: 56045.92 | D53: -202374.54 | E53: 80814.31 | F53: -275970.58 | G53: -177423.81 | H53: -738248.85
A54: % sobre o gerencial | B54: -0.071902514 | C54: 0.019131709 | D54: -0.060750874 | E54: 0.021745069 | F54: -0.063087145 | G54: -0.039086792 | H54: -0.033646505
A55: (+) Lançamentos da Syhus (aba O QUE FAZER) | B55: 174810.87 | C55: -1090.02 | D55: 246153.72 | E55: -65161.35 | F55: 262633.02 | G55: 224613.29 | H55: 841959.53
...

Sheet O QUE FAZER
A1: O QUE FAZER — 138 lançamentos (é só isso)
A2: Todos os erros claros (lançamento em dobro, provisão que nunca foi baixada, MDR da Pagar.me) mais o mínimo que falta pra custo, despesa e total ficarem dentro de 0,5% do gerencial (depois das pendências da Jusfy). Cada linha é um fornecedor, com o nome como está no razão, débito, crédito, NF e a prova. Provisão e baixa do mesmo fornecedor andam juntas. Coluna "Status" é pra Syhus marcar.
A4: Nº | B4: Mês | C4: Fornecedor (razão) | D4: O que fazer | E4: Débito | F4: Crédito | G4: Valor | H4: NF | I4: Por quê (a prova) | J4: Status Syhus
A5: 1 | B5: Jan | C5: DELAINE ILHA DA SILVA 02466060027 | D5: Excluir — lançado em dobro | E5: 342 - Cartão de Crédito - Kamino | F5: 4.1.8.09.002 - Confraternização | G5: 267 | H5: — | I5: Mesmo valor (R$ 267) lançado duas vezes em Jan: a NF 64654684 já está lançada e o pagamento no cartão do mesmo valor também foi lançado como despesa. Excluir o lançamento do cartão.
A6: 2 | B6: Jan | C6: LUCAS ARAUJO SANTOS CONSULTORIA E DESENVOLVIMENTO EM TECNOLOGIA DA INFORMAC | D6: Estornar provisão que nunca foi baixada | E6: 930 - Provisão de Fornecedores | F6: 6.2.1.01.001 - Custos com Serviços de Terceiros - Internos | G6: 49296 | H6: — | I6: Provisão de Jan (R$ 49.296) nunca foi revertida e a NF 17 do mesmo valor entrou em Jan. Estornar a provisão em Jan.
A7: 3 | B7: Jan | C7: ALEXANDER MAX YOKOGAWA CONSULTORIA EM TECNOLOGIA DA INFORMACAO LTDA | D7: Estornar provisão que nunca foi baixada | E7: 930 - Provisão de Fornecedores | F7: 6.2.1.01.001 - Custos com Serviços de Terceiros - Internos | G7: 31667 | H7: — | I7: Provisão de Jan (R$ 31.667) nunca foi revertida. Não há NF desse valor no semestre: estornar.
A8: 4 | B8: Jan | C8: AVA TREINAMENTOS E MENTORIAS LTDA | D8: Estornar provisão que nunca foi baixada | E8: 930 - Provisão de Fornecedores | F8: 4.1.3.01.005 - Influenciadores | G8: 20000 | H8: — | I8: Provisão de Jan (R$ 20.000) nunca foi revertida e a NF 10490 do mesmo valor entrou em Jan. Estornar a provisão em Jan.
A9: 5 | B9: Jan | C9: MONTANDON SARAIVA SERVICOS ADMINISTRATIVOS LTDA | D9: Estornar provisão que nunca foi baixada | E9: 930 - Provisão de Fornecedores | F9: 4.1.3.01.005 - Influenciadores | G9: 5000 | H9: — | I9: Provisão de Jan (R$ 5.000) nunca foi revertida e a NF 1 do mesmo valor entrou em Jan. Estornar a provisão em Jan.
A10: 6 | B10: Jan | C10: 35.376.951 ALBERTO PEREIRA LOPES DA SILVA JUNIOR | D10: Estornar provisão que nunca foi baixada | E10: 930 - Provisão de Fornecedores | F10: 4.1.3.01.005 - Influenciadores | G10: 2000 | H10: — | I10: Provisão de Jan (R$ 2.000) nunca foi revertida. Não há NF desse valor no semestre: estornar.
A11: 7 | B11: Jan | C11: TRETAS JURIDICAS CURSOS E TREINAMENTOS LTDA | D11: Estornar provisão que nunca foi baixada | E11: 930 - Provisão de Fornecedores | F11: 4.1.3.01.005 - Influenciadores | G11: 1000 | H11: — | I11: Provisão de Jan (R$ 1.000) nunca foi revertida e a NF 1 do mesmo valor entrou em Jan. Estornar a provisão em Jan.
A12: 8 | B12: Jan | C12: 52.406.739 BEATRIZ FONSECA SALES | D12: Estornar provisão que nunca foi baixada | E12: 930 - Provisão de Fornecedores | F12: 4.1.3.01.005 - Influenciadores | G12: 900 | H12: — | I12: Provisão de Jan (R$ 900) nunca foi revertida e a NF 9 do mesmo valor entrou em Jan. Estornar a provisão em Jan.
A13: 9 | B13: Jan | C13: MATHEUS JOSE SANTOS DUARTE SOCIEDADE INDIVIDUAL DE ADVOCACIA | D13: Estornar provisão que nunca foi baixada | E13: 930 - Provisão de Fornecedores | F13: 4.1.3.01.005 - Influenciadores | G13: 800 | H13: — | I13: Provisão de Jan (R$ 800) nunca foi revertida e a NF 88 do mesmo valor entrou em Jan. Estornar a provisão em Jan.
A14: 10 | B14: Jan | C14: ZACHARIAS VIEIRA SOCIEDADE INDIVIDUAL DE ADVOCACIA | D14: Estornar provisão que nunca foi baixada | E14: 930 - Provisão de Fornecedores | F14: 4.1.3.01.005 - Influenciadores | G14: 700 | H14: — | I14: Provisão de Jan (R$ 700) nunca foi revertida e a NF 16 do mesmo valor entrou em Jan. Estornar a provisão em Jan.
A15: 11 | B15: Jan | C15: AVA BRASIL EDUCACAO E TECNOLOGIA LTDA | D15: Estornar provisão que nunca foi baixada | E15: 930 - Provisão de Fornecedores | F15: 4.1.3.01.005 - Influenciadores | G15: 582 | H15: — | I15: Provisão de Jan (R$ 582) nunca foi revertida e a NF 77389 do mesmo valor entrou em Jan. Estornar a provisão em Jan.
A16: 12 | B16: Jan | C16: BEYAUT LTDA | D16: Trocar de conta | E16: 6.2.1.01.001 - Custos com Serviços de Terceiros - Internos | F16: 4.1.6.01.007 - Serviços de Terceiros - Internos | G16: 33333.33 | H16: 2, 3 | I16: PJ da área Engenharia (Cadastro). No P&L oficial, só a folha de Engenharia é custo; as demais áreas são despesa. Está na conta 4.1.6.01.007. Mover para 6.2.1.01.001.
... A142: 138 | B142: Jun | C142: PAGAR.ME INSTITUICAO DE PAGAMENTO S.A | D142: Lançar o MDR da Pagar.me (retido no repasse) | E142: 6.2.1.01.003 - Custos com Transações | F142: Pagar.me — valores a receber (conta do repasse) | G142: 57078.91 | H142: — | I142: O P&L tem a taxa cheia da Pagar.me (Payment Processing Fees) e o razão só as NFs de serviço: o MDR retido no repasse (R$ 57.079 no mês) não foi lançado. Lançar pelo extrato de liquidação da Pagar.me.
C143: TOTAL (138 lançamentos, 82 fornecedores)

Sheet Onde a Syhus erra
A1: Onde a Syhus erra — e a regra pra não repetir
A2: Contagem no semestre inteiro (jan a jun), com todos os erros encontrados — não só os 138 lançamentos desta revisão. Seguindo estas regras daqui pra frente, a conciliação do mês fica pequena.
A4: Erro | B4: Vezes | C4: Valor | D4: Exemplos (fornecedor como está no razão) | E4: Regra pra não errar mais
A5: PJ de engenharia lançado como despesa | B5: 78 | C5: 1223585.9 | D5: L. A. B. CAMPOS LTDA; LACERDA GUILHERME CONSULTORIA EM TECNOLOGIA DA INFORMACAO LTDA; DKSWEB DESENVOLVIMENTO DE SOFTWARE LTDA; BEYAUT LTDA | E5: Todo PJ da área de Engenharia (Cadastro) vai em 6.2.1.01.001 (custo). Produto e as demais áreas ficam em 4.1.6.01.007 (despesa) — é assim que está no P&L oficial.
A6: Fornecedor de dados/API lançado como licença ou consultoria | B6: 38 | C6: 1461188.2 | D6: DIGESTO PESQUISA E BANCO DE DADOS LTDA; VIR SERVICOS DE INFORMACOES LTDA; CARBIGDATA TECNOLOGIA E INTELIGENCIA S/A; JUDIT TECNOLOGIA DA INFORMACAO LTDA | E6: Fornecedor de dados/API (Digesto, VIR, Judit, Nova DD, Big Data, Datacube, Carbigdata…) vai em 6.2.1.03.003 — Custo de APIs de Terceiros.
A7: "Mera importação" (4.1.2.05.011) usada como conta de passagem | B7: 37 | C7: 403748.25 | D7: JUDIT TECNOLOGIA DA INFORMACAO LTDA; SOFIA ANY COSTA KALOUSTIAN APOIO ADMINISTRATIVO LTDA; DKSWEB DESENVOLVIMENTO DE SOFTWARE LTDA; ROCHA CASTANHA SOLUCOES LTDA | E7: Não deixar NF parada em 4.1.2.05.011: toda NF importada vai direto pra conta do fornecedor (a mesma dos outros meses).
A8: Compra de equipamento/móvel lançada como despesa | B8: 15 | C8: 205422.35 | D8: EMESUL DECORANDOBEM MATERIAIS DE REVESTIMENTOS; DELL COMPUTADORES DO BRASIL LTDA; KABUM S.A.; PILOTO COMERCIO LTDA | E8: Computador, monitor, móvel e revestimento da sede são imobilizado (1.2.2.01.003), não despesa.
A9: Distrato (rescisão) lançado como custo | B9: 3 | C9: 56525.13 | D9: LUCAS ARAUJO SANTOS CONSULTORIA E DESENVOLVIMENTO EM TECNOLOGIA DA INFORMAC; 50.202.927 FELIPE ALVES DA SILVA; MARCELINO RAMOS DE AVELAR DESENVOLVIMENTO DE SOFTWARES LTDA | E9: Distrato é sempre despesa de RH — Contract Termination (4.1.6.02.007), qualquer que seja a área da pessoa. Não vai em 6.2.1.01.001 nem junto com a NF de serviço.
A10: Outras trocas de conta | B10: 206 | C10: 1469294.2 | D10: MICROSOFT DO BRASIL IMPORTACAO E COMERCIO DE SOFTWARE E VIDEO GAMES LTDA; CORE PRODUCT LTDA; 22793 CONSULTORIA EM TECNOLOGIA DA INFORMACAO LTDA; Renato Sacramento Horta Moreira | E10: Usar sempre a conta que o fornecedor já tem nos outros meses; na dúvida, perguntar à Jusfy antes de lançar.
A11: MDR da Pagar.me não lançado | B11: 6 | C11: 361743.38 | D11: Pagar.me | E11: Todo mês lançar a taxa cheia da Pagar.me pelo extrato de liquidação (o MDR retido no repasse), não só as NFs de serviço.
A12: NF lançada pela data de chegada, não pela competência | B12: 239 | C12: 2266713.9 | D12: AMAZON AWS SERVICOS BRASIL LTDA; DIGESTO PESQUISA E BANCO DE DADOS LTDA; 944279429428 - 005/026 - AMAZON AWS SERVICOS BRASIL LTDA; MICROSOFT DO BRASIL IMPORTACAO E COMERCIO DE SOFTWARE E VIDEO GAMES LTDA | E12: Quando a NF chega depois do mês do serviço: provisionar no mês do serviço (conta 930) e baixar a provisão quando a NF chegar.
A13: Mês sem a despesa do fornecedor (sem NF e sem provisão) | B13: 181 | C13: 1553761.8 | D13: Digesto Pesquisa e Banco de Dados Ltda (Jusbrasil); Amazon Cloud; Vir Servicos de Informacoes Ltda (Correct Data); Microsoft Ads | E13: No fechamento, conferir com a Jusfy os fornecedores recorrentes que ainda não mandaram NF e provisionar pelo valor do mês.
A14: Provisão que nunca foi baixada | B14: 45 | C14: 466957.67 | D14: FACEBOOK SERVICOS ONLINE DO BRASIL LTDA.; LACERDA GUILHERME CONSULTORIA EM TECNOLOGIA DA INFORMACAO LTDA; LUCAS ARAUJO SANTOS CONSULTORIA E DESENVOLVIMENTO EM TECNOLOGIA DA INFORMAC; LATAM AIRLINES BRASIL | E14: Toda provisão tem que ser baixada no mês em que a NF chega — conferir a conta 930 todo fechamento.
A15: Lançado em dobro | B15: 15 | C15: 313512.81 | D15: TREBLE.AI DO BRASIL SERVICOS DIGITAIS LTDA.; Renato Sacramento Horta Moreira; VILA VENTURA HOTEIS LTDA; AVA TREINAMENTOS E MENTORIAS LTDA | E15: Antes de lançar pagamento (cartão, PIX, boleto), conferir se a NF daquele valor já está no razão.
A16: Despesa de 2025 lançada em 2026 | B16: 239 | C16: 1389099 | D16: SWILE DO BRASIL S.A.; DIGESTO PESQUISA E BANCO DE DADOS LTDA; AMAZON AWS SERVICOS BRASIL LTDA; VIR SERVICOS DE INFORMACOES LTDA | E16: No fechamento de dezembro, provisionar o que já se sabe que vai chegar atrasado. (O que já caiu em 2026 fica em 2026 — é só nota explicativa.)
A18: Mudança de regra nesta revisão
A19: Folha de Produto é despesa | E19: No P&L oficial, só a folha de Engenharia é custo ("Engineering & Technology Payroll"). Os PJs de Produto ficam em 4.1.6.01.007 (despesa). As pessoas de Produto que já estão em despesa estão certas.

Sheet DRE Consolidado
A1: DRE contábil consolidado — como vai ficar, conta por conta
A2: Cada célula puxa o subtotal da conta na aba do mês ("Como deve ficar" e "Ajuste"). Embaixo, o gerencial (P&L oficial) e a diferença por grupo. As notas aceitas (competência 2025, taxa Pagar.me, folha) estão explicadas no Resumo.
A4: COMO VAI FICAR (contábil depois dos lançamentos)
A5: Conta | B5: Descrição | C5: Jan | D5: Fev | E5: Mar | F5: Abr | G5: Mai | H5: Jun | I5: Total
A6: 6.2.1.01.001 | B6: Custos com Serviços de Terceiros - Internos | C6: ='Jan'!F5 -> 639620.29 | D6: ='Fev'!F5 -> 470235.67 | E6: ='Mar'!F5 -> 480003.21 | F6: ='Abr'!F5 -> 409310.42 | G6: ='Mai'!F5 -> 367458.8 | H6: ='Jun'!F5 -> 525051.53 | I6: =SUM(C6:H6) -> 2891679.9
A7: 6.2.1.01.003 | B7: Custos com Transações | C7: ='Jan'!F37 -> 82855.93 | D7: ='Fev'!F34 -> 77297.77 | E7: ='Mar'!F36 -> 90261.14 | F7: ='Abr'!F35 -> 88237 | G7: ='Mai'!F41 -> 83647.95 | H7: ='Jun'!F42 -> 81710.51 | I7: =SUM(C7:H7) -> 504010.3
A8: 6.2.1.03.001 | B8: Custo de Hospedagem e Infraestrutura (Cloud) | C8: ='Jan'!F39 -> 221658.88 | D8: ='Fev'!F36 -> 104342.26 | E8: ='Mar'!F38 -> 140383.78 | F8: ='Abr'!F37 -> 269754.87 | G8: ='Mai'!F43 -> 249354.54 | H8: ='Jun'!F44 -> 320313.47 | I8: =SUM(C8:H8) -> 1305807.8
A9: 6.2.1.03.002 | B9: Custo de Licença de Sofware e Sistemas | C9: ='Jan'!F45 -> 350882.47 | D9: ='Fev'!F41 -> 159560.04 | E9: ='Mar'!F43 -> 393235.14 | F9: ='Abr'!F41 -> 385424.66 | G9: ='Mai'!F50 -> 182706.33 | H9: ='Jun'!F53 -> 119226.56 | I9: =SUM(C9:H9) -> 1591035.2
A10: 6.2.1.03.003 | B10: Custo de APIs de Terceiros | C10: ='Jan'!F71 -> 333432.53 | D10: ='Fev'!F60 -> 233105.93 | E10: ='Mar'!F62 -> 102326.52 | F10: ='Abr'!F65 -> 75429.38 | G10: ='Mai'!F72 -> 428744.16 | H10: ='Jun'!F78 -> 426671.54 | I10: =SUM(C10:H10) -> 1599710.1
A11: 4.1.1.01.001 | B11: Salários | C11: ='Jan'!F80 -> 5575.24 | D11: 0 | E11: 0 | F11: 0 | G11: 0 | H11: 0 | I11: =SUM(C11:H11) -> 5575.24
A12: 4.1.1.01.003 | B12: Bolsa Estágio | C12: ='Jan'!F83 -> 1300 | D12: ='Fev'!F70 -> 1500 | E12: ='Mar'!F72 -> 1500 | F12: ='Abr'!F75 -> 1500 | G12: ='Mai'!F86 -> 1500 | H12: ='Jun'!F91 -> 1500 | I12: =SUM(C12:H12) -> 8800
A13: 4.1.1.01.005 | B13: Férias | C13: ='Jan'!F85 -> 125 | D13: ='Fev'!F72 -> 125 | E13: ='Mar'!F74 -> 125 | F13: ='Abr'!F77 -> 125 | G13: ='Mai'!F88 -> 125 | H13: ='Jun'!F93 -> 125 | I13: =SUM(C13:H13) -> 750
A14: 4.1.2.01.001 | B14: Telefonia e Internet | C14: ='Jan'!F87 -> 2897.76 | D14: ='Fev'!F74 -> 2576.51 | E14: ='Mar'!F76 -> 235.52 | F14: ='Abr'!F79 -> 345.42 | G14: ='Mai'!F90 -> 1158.74 | H14: ='Jun'!F95 -> 1800.91 | I14: =SUM(C14:H14) -> 9014.86
A15: 4.1.2.01.002 | B15: Serviços e Equipamentos de TI | C15: 0 | D15: 0 | E15: ='Mar'!F78 -> 13957.29 | F15: ='Abr'!F82 -> 1744.29 | G15: ='Mai'!F93 -> 30963.37 | H15: ='Jun'!F99 -> 16377.65 | I15: =SUM(C15:H15) -> 63042.6
A16: 4.1.2.01.003 | B16: Licença de Sofware e Sistemas (SaaS) | C16: ='Jan'!F94 -> 250115.66 | D16: ='Fev'!F79 -> 83489.94 | E16: ='Mar'!F83 -> 129339.92 | F16: ='Abr'!F85 -> 258182.39 | G16: ='Mai'!F100 -> 150936.52 | H16: ='Jun'!F103 -> 222367.92 | I16: =SUM(C16:H16) -> 1094432.4
A17: 4.1.2.02.001 | B17: Aluguel | C17: ='Jan'!F127 -> 14835.11 | D17: ='Fev'!F106 -> 9105.76 | E17: ='Mar'!F109 -> 17762.35 | F17: ='Abr'!F114 -> 19568.98 | G17: ='Mai'!F137 -> 21930.12 | H17: ='Jun'!F132 -> 18767.06 | I17: =SUM(C17:H17) -> 101969.38
A18: 4.1.2.02.002 | B18: Energia Elétrica | C18: ='Jan'!F131 -> 2983.71 | D18: ='Fev'!F110 -> 3002.34 | E18: ='Mar'!F113 -> 2883.64 | F18: ='Abr'!F118 -> 2882.62 | G18: ='Mai'!F141 -> 2473.96 | H18: ='Jun'!F135 -> 703.71 | I18: =SUM(C18:H18) -> 14929.98
A19: 4.1.2.02.004 | B19: Serviços de Limpeza | C19: 0 | D19: 0 | E19: ='Mar'!F116 -> 2000 | F19: ='Abr'!F121 -> 2000 | G19: ='Mai'!F144 -> 2000 | H19: 0 | I19: =SUM(C19:H19) -> 6000
A20: 4.1.2.02.005 | B20: Manutenções Prediais | C20: ='Jan'!F134 -> 569 | D20: ='Fev'!F113 -> 2769 | E20: 0 | F20: ='Abr'!F123 -> 1453.58 | G20: ='Mai'!F146 -> -473.05 | H20: ='Jun'!F137 -> 1141 | I20: =SUM(C20:H20) -> 5459.53
A21: 4.1.2.04.001 | B21: Passagens Aereas e Rodoviárias | C21: ='Jan'!F136 -> 34210.65 | D21: ='Fev'!F116 -> 58359.7 | E21: ='Mar'!F118 -> 11862.57 | F21: ='Abr'!F128 -> 18995.22 | G21: ='Mai'!F152 -> 14261.79 | H21: ='Jun'!F142 -> 7153.7 | I21: =SUM(C21:H21) -> 144843.63
A22: 4.1.2.04.002 | B22: Lanches e Refeições | C22: ='Jan'!F143 -> 2333.82 | D22: ='Fev'!F127 -> 3814.37 | E22: ='Mar'!F122 -> 1131.89 | F22: ='Abr'!F136 -> 793.24 | G22: ='Mai'!F160 -> 1300.59 | H22: ='Jun'!F145 -> 1422.09 | I22: =SUM(C22:H22) -> 10796
A23: 4.1.2.04.003 | B23: Táxi ou Transportes Executivo | C23: ='Jan'!F146 -> 13412.1 | D23: ='Fev'!F134 -> 3387.44 | E23: ='Mar'!F132 -> 593.99 | F23: ='Abr'!F148 -> 236.84 | G23: ='Mai'!F166 -> 3812.63 | H23: ='Jun'!F160 -> 120.86 | I23: =SUM(C23:H23) -> 21563.86
A24: 4.1.2.04.004 | B24: Pedágio | C24: 0 | D24: ='Fev'!F150 -> 564.5 | E24: ='Mar'!F136 -> 33 | F24: 0 | G24: 0 | H24: 0 | I24: =SUM(C24:H24) -> 597.5
A25: 4.1.2.04.005 | B25: Hotel e Pousadas | C25: ='Jan'!F150 -> 3001.06 | D25: ='Fev'!F153 -> 182073.72 | E25: ='Mar'!F138 -> 3207.72 | F25: ='Abr'!F150 -> 4270.64 | G25: ='Mai'!F173 -> 3417.46 | H25: ='Jun'!F162 -> 3248.8 | I25: =SUM(C25:H25) -> 199219.4
A26: 4.1.2.04.006 | B26: Estacionamento | C26: 0 | D26: 0 | E26: ='Mar'!F142 -> 470 | F26: ='Abr'!F155 -> 193277.8 | G26: ='Mai'!F177 -> 994.76 | H26: 0 | I26: =SUM(C26:H26) -> 194742.56
A27: 4.1.2.04.007 | B27: Combustível | C27: ='Jan'!F153 -> 648.33 | D27: 0 | E27: 0 | F27: 0 | G27: 0 | H27: 0 | I27: =SUM(C27:H27) -> 648.33
A28: 4.1.2.05.001 | B28: Copa e Cozinha | C28: ='Jan'!F155 -> 4589.63 | D28: 0 | E28: ='Mar'!F144 -> 784.95 | F28: ='Abr'!F165 -> 1166.94 | G28: ='Mai'!F179 -> 1767.62 | H28: ='Jun'!F166 -> 1510.32 | I28: =SUM(C28:H28) -> 9819.46
A29: 4.1.2.05.002 | B29: Materiais de Limpeza | C29: ='Jan'!F164 -> 800 | D29: 0 | E29: ='Mar'!F147 -> 6 | F29: ='Abr'!F168 -> 130.6 | G29: ='Mai'!F182 -> 183.45 | H29: ='Jun'!F172 -> 121.25 | I29: =SUM(C29:H29) -> 1241.3
A30: 4.1.2.05.003 | B30: Material de Escritório | C30: ='Jan'!F166 -> 9494.44 | D30: ='Fev'!F157 -> 7452.94 | E30: ='Mar'!F149 -> 407.67 | F30: ='Abr'!F170 -> 206.49 | G30: ='Mai'!F185 -> 450.08 | H30: ='Jun'!F174 -> 519.01 | I30: =SUM(C30:H30) -> 18530.63
A31: 4.1.2.05.005 | B31: Cartório | C31: 0 | D31: 0 | E31: ='Mar'!F154 -> 240.66 | F31: ='Abr'!F173 -> 97.18 | G31: 0 | H31: 0 | I31: =SUM(C31:H31) -> 337.84
A32: 4.1.2.05.007 | B32: Feiras e Eventos | C32: ='Jan'!F176 -> 7000 | D32: ='Fev'!F164 -> 4544.97 | E32: ='Mar'!F157 -> 776.79 | F32: ='Abr'!F175 -> 11875.76 | G32: ='Mai'!F190 -> 4018.9 | H32: ='Jun'!F182 -> 557.7 | I32: =SUM(C32:H32) -> 28774.12
A33: 4.1.2.05.009 | B33: Bens de pequeno valor | C33: ='Jan'!F178 -> 1043.72 | D33: ='Fev'!F168 -> 1177.8 | E33: 0 | F33: 0 | G33: 0 | H33: ='Jun'!F184 -> 4465.87 | I33: =SUM(C33:H33) -> 6687.39
A34: 4.1.2.05.011 | B34: Mera importação | C34: 0 | D34: ='Fev'!F170 -> 267493.78 | E34: 0 | F34: 0 | G34: ='Mai'!F194 -> 8649.77 | H34: 0 | I34: =SUM(C34:H34) -> 276143.55
A35: 4.1.2.05.012 | B35: Fretes | C35: 0 | D35: 0 | E35: 0 | F35: 0 | G35: 0 | H35: ='Jun'!F189 -> 346.82 | I35: =SUM(C35:H35) -> 346.82
A36: 4.1.3.01.001 | B36: Publicidade e Propaganda | C36: ='Jan'!F180 -> 5400 | D36: ='Fev'!F212 -> 2060 | E36: ='Mar'!F160 -> 7464.74 | F36: ='Abr'!F179 -> 260 | G36: ='Mai'!F200 -> 995.26 | H36: ='Jun'!F191 -> 500 | I36: =SUM(C36:H36) -> 16680
A37: 4.1.3.01.002 | B37: Google Ads | C37: ='Jan'!F182 -> 507493.95 | D37: ='Fev'!F215 -> 587911.77 | E37: ='Mar'!F165 -> 832108.38 | F37: ='Abr'!F181 -> 714588.92 | G37: ='Mai'!F203 -> 1057894.2 | H37: ='Jun'!F193 -> 1182057.7 | I37: =SUM(C37:H37) -> 4882054.8
A38: 4.1.3.01.003 | B38: Facebook Ads | C38: ='Jan'!F184 -> 213859 | D38: ='Fev'!F217 -> 127102.17 | E38: ='Mar'!F167 -> 184568.47 | F38: ='Abr'!F183 -> 606552.85 | G38: ='Mai'!F205 -> 732474.29 | H38: ='Jun'!F195 -> 699509.67 | I38: =SUM(C38:H38) -> 2564066.5
A39: 4.1.3.01.004 | B39: Tiktok Ads | C39: ='Jan'!F186 -> 12376.9 | D39: 0 | E39: 0 | F39: 0 | G39: 0 | H39: 0 | I39: =SUM(C39:H39) -> 12376.9
A40: 4.1.3.01.005 | B40: Influenciadores | C40: ='Jan'!F188 -> 59878.64 | D40: ='Fev'!F219 -> 58230 | E40: ='Mar'!F169 -> 63542 | F40: ='Abr'!F185 -> 57095.5 | G40: ='Mai'!F207 -> 33854.5 | H40: ='Jun'!F197 -> 59310.11 | I40: =SUM(C40:H40) -> 331910.75
A41: 4.1.3.01.006 | B41: Microsoft Ads | C41: ='Jan'!F199 -> 35000 | D41: 0 | E41: ='Mar'!F182 -> 49131.91 | F41: 0 | G41: 0 | H41: 0 | I41: =SUM(C41:H41) -> 84131.91
...

Sheet Jan
A1: Janeiro/2026 — DRE contábil aberto por conta e fornecedor
A2: Cada conta do DRE com os fornecedores do razão (nome como está no livro da Syhus). "Como está" = razão de hoje. "Ajuste" = os lançamentos da aba O QUE FAZER (nº na coluna G). "Como deve ficar" = como a conta fica depois. Os subtotais e totais são fórmulas.
A4: Conta | B4: Descrição | C4: Fornecedor (razão) | D4: Como está | E4: Ajuste | F4: Como deve ficar | G4: Lançamento nº | H4: Observação
A5: 6.2.1.01.001 | B5: Custos com Serviços de Terceiros - Internos | C5: TOTAL DA CONTA | D5: =SUM(D6:D36) -> 647583.29 | E5: =SUM(E6:E36) -> -7963 | F5: =SUM(F6:F36) -> 639620.29
C6: LUCAS ARAUJO SANTOS CONSULTORIA E DESENVOLVIMENTO EM TECNOLOGIA DA INFORMAC | D6: 98591.7 | E6: -49296 | F6: =D6+E6 -> 49295.7 | G6: 2
C7: BEYAUT LTDA | D7: 0 | E7: 33333.33 | F7: =D7+E7 -> 33333.33 | G7: 12
C8: ALEXANDER MAX YOKOGAWA CONSULTORIA EM TECNOLOGIA DA INFORMACAO LTDA | D8: 63333.67 | E8: -31667 | F8: =D8+E8 -> 31666.67 | G8: 3 | H8: Tem R$ 12.667 de competência 2025: fica em 2026 (exercício encerrado), é nota explicativa.
C9: BLUE ENGENHARIA EM SOFTWARE LTDA | D9: 0 | E9: 22166.67 | F9: =D9+E9 -> 22166.67 | G9: 13
C10: IVAN P. DOS SANTOS LTDA | D10: 0 | E10: 17500 | F10: =D10+E10 -> 17500 | G10: 14
C11: CORE PRODUCT LTDA | D11: 49350 | E11: 0 | F11: =D11+E11 -> 49350
C12: LACERDA GUILHERME CONSULTORIA EM TECNOLOGIA DA INFORMACAO LTDA | D12: 33250 | E12: 0 | F12: =D12+E12 -> 33250
C13: DOUGLAS LIMA MACHADO 02831827094 | D13: 29851 | E13: 0 | F13: =D13+E13 -> 29851
C14: POLYANA CHAMAS FALCAO LTDA | D14: 28500 | E14: 0 | F14: =D14+E14 -> 28500 | H14: Tem R$ 9.500 de competência 2025: fica em 2026 (exercício encerrado), é nota explicativa.
C15: LEONARDO PIECHA CALDEIRA LTDA | D15: 26916.67 | E15: 0 | F15: =D15+E15 -> 26916.67 | H15: Tem R$ 9.917 de competência 2025: fica em 2026 (exercício encerrado), é nota explicativa.
C16: 36.256.578 CHRISTIAN RODRIGO CORRALES | D16: 26809.13 | E16: 0 | F16: =D16+E16 -> 26809.13 | H16: Tem R$ 13.125 de competência 2025: fica em 2026 (exercício encerrado), é nota explicativa.
C17: HIGOR SANTOS DE JESUS LTDA | D17: 25333.33 | E17: 0 | F17: =D17+E17 -> 25333.33 | H17: Tem R$ 9.333 de competência 2025: fica em 2026 (exercício encerrado), é nota explicativa.
C18: 50.202.927 FELIPE ALVES DA SILVA | D18: 23592.03 | E18: 0 | F18: =D18+E18 -> 23592.03 | H18: Tem R$ 11.550 de competência 2025: fica em 2026 (exercício encerrado), é nota explicativa.
C19: 54.652.017 JOAO VITOR DE MORAIS ROCHA | D19: 22500 | E19: 0 | F19: =D19+E19 -> 22500 | H19: Tem R$ 9.000 de competência 2025: fica em 2026 (exercício encerrado), é nota explicativa.
C20: BAS DIGITAL LTDA | D20: 21000 | E20: 0 | F20: =D20+E20 -> 21000 | H20: Tem R$ 7.000 de competência 2025: fica em 2026 (exercício encerrado), é nota explicativa.
C21: MARCOS THIAGO SILVESTRE DE MORAES CONSULTORIA EM TECNOLOGIA DA INFORMACAO LTDA | D21: 20000 | E21: 0 | F21: =D21+E21 -> 20000
C22: 61.806.165 MARILIA MARAGNO PEGORARO | D22: 19724.48 | E22: 0 | F22: =D22+E22 -> 19724.48
C23: THIAGO AUGUSTO DE OLIVEIRA TECNOLOGIA DA INFORMACAO LTDA | D23: 17500 | E23: 0 | F23: =D23+E23 -> 17500
C24: DANIEL GERONIMO DO AMARAL 02303012236 | D24: 14106.2 | E24: 0 | F24: =D24+E24 -> 14106.2 | H24: Tem R$ 6.906 de competência 2025: fica em 2026 (exercício encerrado), é nota explicativa.
C25: 4TECH DESENVOLVIMENTO DE SOFTWARES LTDA | D25: 14106.2 | E25: 0 | F25: =D25+E25 -> 14106.2 | H25: Tem R$ 6.906 de competência 2025: fica em 2026 (exercício encerrado), é nota explicativa.
C26: MARIA DE FATIMA BARBOSA CARDOSO DESENVOLVIMENTO DE SOFTWARE LTDA | D26: 13750 | E26: 0 | F26: =D26+E26 -> 13750 | H26: Tem R$ 2.750 de competência 2025: fica em 2026 (exercício encerrado), é nota explicativa.
C27: MARCELINO RAMOS DE AVELAR DESENVOLVIMENTO DE SOFTWARES LTDA | D27: 13064.52 | E27: 0 | F27: =D27+E27 -> 13064.52
C28: GUSTAVO HENRIQUE SILVA CONSULTORIA EM TECNOLOGIA DA INFORMACAO LTDA | D28: 13000 | E28: 0 | F28: =D28+E28 -> 13000
C29: JOSE RICARDO ALVES FIGUEIROA DESENVOLVIMENTO DE SOFTWARE LTDA | D29: 12500 | E29: 0 | F29: =D29+E29 -> 12500
C30: NORTHON VINICIOS CARDOSO SOARES LTDA | D30: 12000 | E30: 0 | F30: =D30+E30 -> 12000 | H30: Tem R$ 3.000 de competência 2025: fica em 2026 (exercício encerrado), é nota explicativa.
C31: Ivan Pedroso dos Santos - 46 | D31: 11666.67 | E31: 0 | F31: =D31+E31 -> 11666.67 | H31: Tem R$ 11.667 de competência 2025: fica em 2026 (exercício encerrado), é nota explicativa.
C32: MEANI DOS SANTOS FREITAS LTDA | D32: 11333.33 | E32: 0 | F32: =D32+E32 -> 11333.33 | H32: Tem R$ 2.833 de competência 2025: fica em 2026 (exercício encerrado), é nota explicativa.
C33: SAMUELSON DE BRITO MESQUITA 02197364219 | D33: 9000 | E33: 0 | F33: =D33+E33 -> 9000
C34: 50.836.277 DIEGO ALVES FERREIRA | D34: 7721.03 | E34: 0 | F34: =D34+E34 -> 7721.03 | H34: Tem R$ 3.780 de competência 2025: fica em 2026 (exercício encerrado), é nota explicativa.
C35: 62.516.834 DAVI GRACIANO NASCIMENTO COSTA | D35: 5333.33 | E35: 0 | F35: =D35+E35 -> 5333.33 | H35: Tem R$ 1.333 de competência 2025: fica em 2026 (exercício encerrado), é nota explicativa.
C36: LUIS EMANUEL RIGON ALDERETE DESENVOLVIMENTO DE SOFTWARE LTDA | D36: 3750 | E36: 0 | F36: =D36+E36 -> 3750 | H36: Tem R$ 1.250 de competência 2025: fica em 2026 (exercício encerrado), é nota explicativa.
A37: 6.2.1.01.003 | B37: Custos com Transações | C37: TOTAL DA CONTA | D37: =SUM(D38:D38) -> 22660.18 | E37: =SUM(E38:E38) -> 60195.75 | F37: =SUM(F38:F38) -> 82855.93
C38: PAGAR.ME INSTITUICAO DE PAGAMENTO S.A | D38: 22660.18 | E38: 60195.75 | F38: =D38+E38 -> 82855.93 | G38: 24
A39: 6.2.1.03.001 | B39: Custo de Hospedagem e Infraestrutura (Cloud) | C39: TOTAL DA CONTA | D39: =SUM(D40:D44) -> 123490.2 | E39: =SUM(E40:E44) -> 98168.68 | F39: =SUM(F40:F44) -> 221658.88
C40: AMAZON AWS SERVICOS BRASIL LTDA | D40: 107263.42 | E40: 95555.68 | F40: =D40+E40 -> 202819.1 | G40: 15 | H40: Tem R$ 107.263 de competência 2025: fica em 2026 (exercício encerrado), é nota explicativa.
C41: NT - 001/001 - GODADDY BRASIL | D41: 0 | E41: 2613 | F41: =D41+E41 -> 2613 | G41: 23
...

Sheet Fev
A1: Fevereiro/2026 — DRE contábil aberto por conta e fornecedor
A2: Cada conta do DRE com os fornecedores do razão (nome como está no livro da Syhus). "Como está" = razão de hoje. "Ajuste" = os lançamentos da aba O QUE FAZER (nº na coluna G). "Como deve ficar" = como a conta fica depois. Os subtotais e totais são fórmulas.
A4: Conta | B4: Descrição | C4: Fornecedor (razão) | D4: Como está | E4: Ajuste | F4: Como deve ficar | G4: Lançamento nº | H4: Observação
A5: 6.2.1.01.001 | B5: Custos com Serviços de Terceiros - Internos | C5: TOTAL DA CONTA | D5: =SUM(D6:D33) -> 331117.39 | E5: =SUM(E6:E33) -> 139118.28 | F5: =SUM(F6:F33) -> 470235.67
C6: L. A. B. CAMPOS LTDA | D6: 0 | E6: 30000 | F6: =D6+E6 -> 30000 | G6: 30
C7: DKSWEB DESENVOLVIMENTO DE SOFTWARE LTDA | D7: 0 | E7: 26000 | F7: =D7+E7 -> 26000 | G7: 31
C8: BEYAUT LTDA | D8: 0 | E8: 20000 | F8: =D8+E8 -> 20000 | G8: 33
C9: LACERDA GUILHERME CONSULTORIA EM TECNOLOGIA DA INFORMACAO LTDA | D9: 0 | E9: 19000 | F9: =D9+E9 -> 19000 | G9: 34
C10: ALEXANDER MAX YOKOGAWA CONSULTORIA EM TECNOLOGIA DA INFORMACAO LTDA | D10: 0 | E10: 19000 | F10: =D10+E10 -> 19000 | G10: 35
C11: THIAGO AUGUSTO DE OLIVEIRA TECNOLOGIA DA INFORMACAO LTDA | D11: 0 | E11: 17500 | F11: =D11+E11 -> 17500 | G11: 36
C12: DOUGLAS LIMA MACHADO 02831827094 | D12: 0 | E12: 7618.28 | F12: =D12+E12 -> 7618.28 | G12: 37
C13: Renato Sacramento Horta Moreira | D13: 50000 | E13: 0 | F13: =D13+E13 -> 50000
C14: CORE PRODUCT LTDA | D14: 50000 | E14: 0 | F14: =D14+E14 -> 50000
C15: POLYANA CHAMAS FALCAO LTDA | D15: 34607.14 | E15: 0 | F15: =D15+E15 -> 34607.14
C16: MARCOS THIAGO SILVESTRE DE MORAES CONSULTORIA EM TECNOLOGIA DA INFORMACAO LTDA | D16: 20000 | E16: 0 | F16: =D16+E16 -> 20000
C17: LEONARDO PIECHA CALDEIRA LTDA | D17: 17000 | E17: 0 | F17: =D17+E17 -> 17000
C18: HIGOR SANTOS DE JESUS LTDA | D18: 16000 | E18: 0 | F18: =D18+E18 -> 16000
C19: BAS DIGITAL LTDA | D19: 14000 | E19: 0 | F19: =D19+E19 -> 14000
C20: 36.256.578 CHRISTIAN RODRIGO CORRALES | D20: 13684.13 | E20: 0 | F20: =D20+E20 -> 13684.13
C21: 54.652.017 JOAO VITOR DE MORAIS ROCHA | D21: 13500 | E21: 0 | F21: =D21+E21 -> 13500
C22: GUSTAVO HENRIQUE SILVA CONSULTORIA EM TECNOLOGIA DA INFORMACAO LTDA | D22: 13000 | E22: 0 | F22: =D22+E22 -> 13000
C23: JOSE RICARDO ALVES FIGUEIROA DESENVOLVIMENTO DE SOFTWARE LTDA | D23: 12500 | E23: 0 | F23: =D23+E23 -> 12500
C24: 50.202.927 FELIPE ALVES DA SILVA | D24: 12042.03 | E24: 0 | F24: =D24+E24 -> 12042.03
... C33: LUIS EMANUEL RIGON ALDERETE DESENVOLVIMENTO DE SOFTWARE LTDA | D33: 2500 | E33: 0 | F33: =D33+E33 -> 2500
A34: 6.2.1.01.003 | B34: Custos com Transações | C34: TOTAL DA CONTA | D34: =SUM(D35:D35) -> 22010 | E34: =SUM(E35:E35) -> 55287.77 | F34: =SUM(F35:F35) -> 77297.77
C35: PAGAR.ME INSTITUICAO DE PAGAMENTO S.A | D35: 22010 | E35: 55287.77 | F35: =D35+E35 -> 77297.77 | G35: 44
A36: 6.2.1.03.001 | B36: Custo de Hospedagem e Infraestrutura (Cloud) | C36: TOTAL DA CONTA | D36: =SUM(D37:D40) -> 111623.7 | E36: =SUM(E37:E40) -> -7281.44 | F36: =SUM(F37:F40) -> 104342.26
C37: AMAZON AWS SERVICOS BRASIL LTDA | D37: 95555.68 | E37: -7281.44 | F37: =D37+E37 -> 88274.24 | G37: 38, 39
C38: GOOGLE CLOUD BRASIL COMPUTACAO E SERVICOS DE DADOS LTDA. | D38: 8759.48 | E38: 0 | F38: =D38+E38 -> 8759.48
C39: WEBSHARE* PROXY PLN YF | D39: 4047.69 | E39: 0 | F39: =D39+E39 -> 4047.69
C40: PADDLE | D40: 3260.85 | E40: 0 | F40: =D40+E40 -> 3260.85
A41: 6.2.1.03.002 | B41: Custo de Licença de Sofware e Sistemas | C41: TOTAL DA CONTA | D41: =SUM(D42:D59) -> 159560.04 | E41: =SUM(E42:E59) -> 0 | F41: =SUM(F42:F59) -> 159560.04
C42: VIR SERVICOS DE INFORMACOES LTDA | D42: 79731.8 | E42: 0 | F42: =D42+E42 -> 79731.8
C43: NOVA DD POSITIVO REPRESENTACOES LTDA. | D43: 44079.32 | E43: 0 | F43: =D43+E43 -> 44079.32
C44: POTELO SISTEMAS DE INFORMACAO LTDA | D44: 10000 | E44: 0 | F44: =D44+E44 -> 10000
C45: TWILIO SEGMENT | D45: 4789.62 | E45: 0 | F45: =D45+E45 -> 4789.62
C46: ATLASSIAN JIRA | D46: 4462.85 | E46: 0 | F46: =D46+E46 -> 4462.85
C47: METABASE INC | D47: 3400.62 | E47: 0 | F47: =D47+E47 -> 3400.62
C48: BAGOLIN E BASTIANELLO CONSULTORIA LTDA | D48: 3000 | E48: 0 | F48: =D48+E48 -> 3000
C49: OPENAI CHATGPT | D49: 2094.05 | E49: 0 | F49: =D49+E49 -> 2094.05
...

Sheet Mar
A1: Março/2026 — DRE contábil aberto por conta e fornecedor
A2: Cada conta do DRE com os fornecedores do razão (nome como está no livro da Syhus). "Como está" = razão de hoje. "Ajuste" = os lançamentos da aba O QUE FAZER (nº na coluna G). "Como deve ficar" = como a conta fica depois. Os subtotais e totais são fórmulas.
A4: Conta | B4: Descrição | C4: Fornecedor (razão) | D4: Como está | E4: Ajuste | F4: Como deve ficar | G4: Lançamento nº | H4: Observação
A5: 6.2.1.01.001 | B5: Custos com Serviços de Terceiros - Internos | C5: TOTAL DA CONTA | D5: =SUM(D6:D35) -> 380723.21 | E5: =SUM(E6:E35) -> 99280 | F5: =SUM(F6:F35) -> 480003.21
C6: L. A. B. CAMPOS LTDA | D6: 0 | E6: 30000 | F6: =D6+E6 -> 30000 | G6: 50
C7: DKSWEB DESENVOLVIMENTO DE SOFTWARE LTDA | D7: 0 | E7: 26000 | F7: =D7+E7 -> 26000 | G7: 51
C8: BEYAUT LTDA | D8: 0 | E8: 22000 | F8: =D8+E8 -> 22000 | G8: 53
C9: LACERDA GUILHERME CONSULTORIA EM TECNOLOGIA DA INFORMACAO LTDA | D9: 0 | E9: 21280 | F9: =D9+E9 -> 21280 | G9: 54
C10: CORE PRODUCT LTDA | D10: 50000 | E10: 0 | F10: =D10+E10 -> 50000
C11: LUCAS ROBERTO FRANZON PASSELI 43946514847 | D11: 38766.06 | E11: 0 | F11: =D11+E11 -> 38766.06 | H11: Tem R$ 7.560 de competência 2025: fica em 2026 (exercício encerrado), é nota explicativa.
C12: MARCOS THIAGO SILVESTRE DE MORAES CONSULTORIA EM TECNOLOGIA DA INFORMACAO LTDA | D12: 20000 | E12: 0 | F12: =D12+E12 -> 20000
C13: ALEXANDER MAX YOKOGAWA CONSULTORIA EM TECNOLOGIA DA INFORMACAO LTDA | D13: 19000 | E13: 0 | F13: =D13+E13 -> 19000
C14: LEONARDO PIECHA CALDEIRA LTDA | D14: 18700 | E14: 0 | F14: =D14+E14 -> 18700
C15: IVAN P. DOS SANTOS LTDA | D15: 17500 | E15: 0 | F15: =D15+E15 -> 17500
C16: THIAGO AUGUSTO DE OLIVEIRA TECNOLOGIA DA INFORMACAO LTDA | D16: 17500 | E16: 0 | F16: =D16+E16 -> 17500
C17: HIGOR SANTOS DE JESUS LTDA | D17: 16000 | E17: 0 | F17: =D17+E17 -> 16000
C18: 36.256.578 CHRISTIAN RODRIGO CORRALES | D18: 15736.75 | E18: 0 | F18: =D18+E18 -> 15736.75
C19: BAS DIGITAL LTDA | D19: 14000 | E19: 0 | F19: =D19+E19 -> 14000
C20: 54.652.017 JOAO VITOR DE MORAIS ROCHA | D20: 13500 | E20: 0 | F20: =D20+E20 -> 13500
C21: 65.279.421 JULIA THIESEN SCHERER | D21: 13000 | E21: 0 | F21: =D21+E21 -> 13000
C22: GUSTAVO HENRIQUE SILVA CONSULTORIA EM TECNOLOGIA DA INFORMACAO LTDA | D22: 13000 | E22: 0 | F22: =D22+E22 -> 13000
C23: JOSE RICARDO ALVES FIGUEIROA DESENVOLVIMENTO DE SOFTWARE LTDA | D23: 12500 | E23: 0 | F23: =D23+E23 -> 12500
... C35: 62.516.834 DAVI GRACIANO NASCIMENTO COSTA | D35: 4000 | E35: 0 | F35: =D35+E35 -> 4000
A36: 6.2.1.01.003 | B36: Custos com Transações | C36: TOTAL DA CONTA | D36: =SUM(D37:D37) -> 25001.26 | E36: =SUM(E37:E37) -> 65259.88 | F36: =SUM(F37:F37) -> 90261.14
C37: PAGAR.ME INSTITUICAO DE PAGAMENTO S.A | D37: 25001.26 | E37: 65259.88 | F37: =D37+E37 -> 90261.14 | G37: 62
A38: 6.2.1.03.001 | B38: Custo de Hospedagem e Infraestrutura (Cloud) | C38: TOTAL DA CONTA | D38: =SUM(D39:D42) -> 121274.58 | E38: =SUM(E39:E42) -> 19109.2 | F38: =SUM(F39:F42) -> 140383.78
C39: AMAZON AWS SERVICOS BRASIL LTDA | D39: 88274.24 | E39: 19109.2 | F39: =D39+E39 -> 107383.44 | G39: 55, 56
C40: GOOGLE CLOUD BRASIL COMPUTACAO E SERVICOS DE DADOS LTDA. | D40: 26860.75 | E40: 0 | F40: =D40+E40 -> 26860.75
C41: WEBSHARE RNW PROXY 42 | D41: 4002.91 | E41: 0 | F41: =D41+E41 -> 4002.91
C42: PADDLE | D42: 2136.68 | E42: 0 | F42: =D42+E42 -> 2136.68
A43: 6.2.1.03.002 | B43: Custo de Licença de Sofware e Sistemas | C43: TOTAL DA CONTA | D43: =SUM(D44:D61) -> 388452.89 | E43: =SUM(E44:E61) -> 4782.25 | F43: =SUM(F44:F61) -> 393235.14
C44: TWILIO SEGMENT | D44: 0 | E44: 4782.25 | F44: =D44+E44 -> 4782.25 | G44: 60
C45: DIGESTO PESQUISA E BANCO DE DADOS LTDA | D45: 151942.35 | E45: 0 | F45: =D45+E45 -> 151942.35
C46: VIR SERVICOS DE INFORMACOES LTDA | D46: 94428 | E46: 0 | F46: =D46+E46 -> 94428
C47: NOVA DD POSITIVO REPRESENTACOES LTDA. | D47: 47580.42 | E47: 0 | F47: =D47+E47 -> 47580.42
C48: JUDIT TECNOLOGIA DA INFORMACAO LTDA | D48: 37176.35 | E48: 0 | F48: =D48+E48 -> 37176.35
C49: CARBIGDATA TECNOLOGIA E INTELIGENCIA S/A | D49: 24060 | E49: 0 | F49: =D49+E49 -> 24060
C50: APPCUES | D50: 18827 | E50: 0 | F50: =D50+E50 -> 18827
C51: POTELO SISTEMAS DE INFORMACAO LTDA | D51: 10000 | E51: 0 | F51: =D51+E51 -> 10000
C52: BAGOLIN E BASTIANELLO CONSULTORIA LTDA | D52: 3000 | E52: 0 | F52: =D52+E52 -> 3000
...

Sheet Abr
A1: Abril/2026 — DRE contábil aberto por conta e fornecedor
A2: Cada conta do DRE com os fornecedores do razão (nome como está no livro da Syhus). "Como está" = razão de hoje. "Ajuste" = os lançamentos da aba O QUE FAZER (nº na coluna G). "Como deve ficar" = como a conta fica depois. Os subtotais e totais são fórmulas.
A4: Conta | B4: Descrição | C4: Fornecedor (razão) | D4: Como está | E4: Ajuste | F4: Como deve ficar | G4: Lançamento nº | H4: Observação
A5: 6.2.1.01.001 | B5: Custos com Serviços de Terceiros - Internos | C5: TOTAL DA CONTA | D5: =SUM(D6:D34) -> 265310.42 | E5: =SUM(E6:E34) -> 144000 | F5: =SUM(F6:F34) -> 409310.42
C6: GABRIELA BORCA SERVICOS DE APOIO ADMINISTRATIVO LTDA | D6: -35000 | E6: 35000 | F6: =D6+E6 -> 0 | G6: 63
C7: L. A. B. CAMPOS LTDA | D7: 0 | E7: 30000 | F7: =D7+E7 -> 30000 | G7: 64
C8: DKSWEB DESENVOLVIMENTO DE SOFTWARE LTDA | D8: 0 | E8: 26000 | F8: =D8+E8 -> 26000 | G8: 66
C9: BEYAUT LTDA | D9: 0 | E9: 22000 | F9: =D9+E9 -> 22000 | G9: 67
C10: IVAN P. DOS SANTOS LTDA | D10: 0 | E10: 17500 | F10: =D10+E10 -> 17500 | G10: 68
C11: BATISTA SOLUCOES EM TECNOLOGIA LTDA | D11: 0 | E11: 13500 | F11: =D11+E11 -> 13500 | G11: 69
C12: CORE PRODUCT LTDA | D12: 50000 | E12: 0 | F12: =D12+E12 -> 50000
C13: MARCOS THIAGO SILVESTRE DE MORAES CONSULTORIA EM TECNOLOGIA DA INFORMACAO LTDA | D13: 20000 | E13: 0 | F13: =D13+E13 -> 20000
C14: ALEXANDER MAX YOKOGAWA CONSULTORIA EM TECNOLOGIA DA INFORMACAO LTDA | D14: 19000 | E14: 0 | F14: =D14+E14 -> 19000
C15: LEONARDO PIECHA CALDEIRA LTDA | D15: 18700 | E15: 0 | F15: =D15+E15 -> 18700
C16: THIAGO AUGUSTO DE OLIVEIRA TECNOLOGIA DA INFORMACAO LTDA | D16: 17500 | E16: 0 | F16: =D16+E16 -> 17500
C17: HIGOR SANTOS DE JESUS LTDA | D17: 16000 | E17: 0 | F17: =D17+E17 -> 16000
C18: 36.256.578 CHRISTIAN RODRIGO CORRALES | D18: 15736.75 | E18: 0 | F18: =D18+E18 -> 15736.75
C19: 50.202.927 FELIPE ALVES DA SILVA | D19: 15253.24 | E19: 0 | F19: =D19+E19 -> 15253.24
C20: BAS DIGITAL LTDA | D20: 14000 | E20: 0 | F20: =D20+E20 -> 14000
C21: 54.652.017 JOAO VITOR DE MORAIS ROCHA | D21: 13500 | E21: 0 | F21: =D21+E21 -> 13500
C22: GUSTAVO HENRIQUE SILVA CONSULTORIA EM TECNOLOGIA DA INFORMACAO LTDA | D22: 13000 | E22: 0 | F22: =D22+E22 -> 13000
C23: JOSE RICARDO ALVES FIGUEIROA DESENVOLVIMENTO DE SOFTWARE LTDA | D23: 12500 | E23: 0 | F23: =D23+E23 -> 12500
... C34: SWILE DO BRASIL S.A. | D34: 2102.31 | E34: 0 | F34: =D34+E34 -> 2102.31
A35: 6.2.1.01.003 | B35: Custos com Transações | C35: TOTAL DA CONTA | D35: =SUM(D36:D36) -> 23802.94 | E35: =SUM(E36:E36) -> 64434.06 | F35: =SUM(F36:F36) -> 88237
C36: PAGAR.ME INSTITUICAO DE PAGAMENTO S.A | D36: 23802.94 | E36: 64434.06 | F36: =D36+E36 -> 88237 | G36: 79
A37: 6.2.1.03.001 | B37: Custo de Hospedagem e Infraestrutura (Cloud) | C37: TOTAL DA CONTA | D37: =SUM(D38:D40) -> 271058.44 | E37: =SUM(E38:E40) -> -1303.57 | F37: =SUM(F38:F40) -> 269754.87
C38: AMAZON AWS SERVICOS BRASIL LTDA | D38: 107383.44 | E38: -1303.57 | F38: =D38+E38 -> 106079.87 | G38: 71, 77
C39: GOOGLE CLOUD BRASIL COMPUTACAO E SERVICOS DE DADOS LTDA. | D39: 161612.46 | E39: 0 | F39: =D39+E39 -> 161612.46
C40: PADDLE | D40: 2062.54 | E40: 0 | F40: =D40+E40 -> 2062.54
A41: 6.2.1.03.002 | B41: Custo de Licença de Sofware e Sistemas | C41: TOTAL DA CONTA | D41: =SUM(D42:D64) -> 385424.66 | E41: =SUM(E42:E64) -> 0 | F41: =SUM(F42:F64) -> 385424.66
C42: DIGESTO PESQUISA E BANCO DE DADOS LTDA | D42: 161483.1 | E42: 0 | F42: =D42+E42 -> 161483.1
C43: VIR SERVICOS DE INFORMACOES LTDA | D43: 102915 | E43: 0 | F43: =D43+E43 -> 102915
C44: CARBIGDATA TECNOLOGIA E INTELIGENCIA S/A | D44: 42504 | E44: 0 | F44: =D44+E44 -> 42504
C45: JUDIT TECNOLOGIA DA INFORMACAO LTDA | D45: 41990.75 | E45: 0 | F45: =D45+E45 -> 41990.75
C46: POTELO SISTEMAS DE INFORMACAO LTDA | D46: 10000 | E46: 0 | F46: =D46+E46 -> 10000
C47: TWILIO SEGMENT | D47: 4578.7 | E47: 0 | F47: =D47+E47 -> 4578.7
C48: OPENAI CHATGPT | D48: 4082.46 | E48: 0 | F48: =D48+E48 -> 4082.46
C49: ATLASSIAN | D49: 4010.81 | E49: 0 | F49: =D49+E49 -> 4010.81
C50: METABASE INC | D50: 3355.87 | E50: 0 | F50: =D50+E50 -> 3355.87
C51: BAGOLIN E BASTIANELLO CONSULTORIA LTDA | D51: 3000 | E51: 0 | F51: =D51+E51 -> 3000
...

Sheet Mai
A1: Maio/2026 — DRE contábil aberto por conta e fornecedor
A2: Cada conta do DRE com os fornecedores do razão (nome como está no livro da Syhus). "Como está" = razão de hoje. "Ajuste" = os lançamentos da aba O QUE FAZER (nº na coluna G). "Como deve ficar" = como a conta fica depois. Os subtotais e totais são fórmulas.
A4: Conta | B4: Descrição | C4: Fornecedor (razão) | D4: Como está | E4: Ajuste | F4: Como deve ficar | G4: Lançamento nº | H4: Observação
A5: 6.2.1.01.001 | B5: Custos com Serviços de Terceiros - Internos | C5: TOTAL DA CONTA | D5: =SUM(D6:D40) -> 273982.74 | E5: =SUM(E6:E40) -> 93476.06 | F5: =SUM(F6:F40) -> 367458.8
C6: LACERDA GUILHERME CONSULTORIA EM TECNOLOGIA DA INFORMACAO LTDA | D6: 0 | E6: 40280 | F6: =D6+E6 -> 40280 | G6: 100
C7: L. A. B. CAMPOS LTDA | D7: 0 | E7: 30000 | F7: =D7+E7 -> 30000 | G7: 101
C8: DKSWEB DESENVOLVIMENTO DE SOFTWARE LTDA | D8: 0 | E8: 26000 | F8: =D8+E8 -> 26000 | G8: 102
C9: LUCAS ROBERTO FRANZON PASSELI 43946514847 | D9: 0 | E9: 7882.06 | F9: =D9+E9 -> 7882.06 | G9: 116
C10: Kauan Portela | D10: 6906 | E10: -6906 | F10: =D10+E10 -> 0 | G10: 84
C11: Diego Alves | D11: 3780 | E11: -3780 | F11: =D11+E11 -> 0 | G11: 88
C12: IVAN P. DOS SANTOS LTDA | D12: 23333.33 | E12: 0 | F12: =D12+E12 -> 23333.33
C13: MARCOS THIAGO SILVESTRE DE MORAES CONSULTORIA EM TECNOLOGIA DA INFORMACAO LTDA | D13: 20000 | E13: 0 | F13: =D13+E13 -> 20000
C14: ALEXANDER MAX YOKOGAWA CONSULTORIA EM TECNOLOGIA DA INFORMACAO LTDA | D14: 19000 | E14: 0 | F14: =D14+E14 -> 19000
C15: LEONARDO PIECHA CALDEIRA LTDA | D15: 18700 | E15: 0 | F15: =D15+E15 -> 18700
C16: THIAGO AUGUSTO DE OLIVEIRA TECNOLOGIA DA INFORMACAO LTDA | D16: 17500 | E16: 0 | F16: =D16+E16 -> 17500
C17: HAGROEX LTDA | D17: 17000 | E17: 0 | F17: =D17+E17 -> 17000
C18: HIGOR SANTOS DE JESUS LTDA | D18: 16000 | E18: 0 | F18: =D18+E18 -> 16000
C19: 36.256.578 CHRISTIAN RODRIGO CORRALES | D19: 15736.75 | E19: 0 | F19: =D19+E19 -> 15736.75
C20: s Mensal- Ramon de Sousa Pereira [Oficial] | D20: -15500 | E20: 0 | F20: =D20+E20 -> -15500 | H20: Tem R$ 15.500 de competência 2025: fica em 2026 (exercício encerrado), é nota explicativa.
C21: Mensal - Ramon - s - Ramon de Sousa Pereira | D21: -15500 | E21: 0 | F21: =D21+E21 -> -15500 | H21: Tem R$ 15.500 de competência 2025: fica em 2026 (exercício encerrado), é nota explicativa.
C22: BAS DIGITAL LTDA | D22: 14000 | E22: 0 | F22: =D22+E22 -> 14000
C23: 54.652.017 JOAO VITOR DE MORAIS ROCHA | D23: 13500 | E23: 0 | F23: =D23+E23 -> 13500
C24: GUSTAVO HENRIQUE SILVA CONSULTORIA EM TECNOLOGIA DA INFORMACAO LTDA | D24: 13000 | E24: 0 | F24: =D24+E24 -> 13000
C25: JOSE RICARDO ALVES FIGUEIROA DESENVOLVIMENTO DE SOFTWARE LTDA | D25: 12500 | E25: 0 | F25: =D25+E25 -> 12500
C26: MARIA DE FATIMA BARBOSA CARDOSO DESENVOLVIMENTO DE SOFTWARE LTDA | D26: 11000 | E26: 0 | F26: =D26+E26 -> 11000
C27: NORTHON VINICIOS CARDOSO SOARES LTDA | D27: 10800 | E27: 0 | F27: =D27+E27 -> 10800
C28: Juan Carlo | D28: 10000 | E28: 0 | F28: =D28+E28 -> 10000
C29: KAYRO DANYELL ALVES CONSULTORIA EM TECNOLOGIA DA INFORMACAO LTDA | D29: 10000 | E29: 0 | F29: =D29+E29 -> 10000
C30: EDUARDO HENRIQUE KATSURAYAMA ABREU CONSULTORIA EM TECNOLOGIA DA INFORMACAO LTDA | D30: 9032.26 | E30: 0 | F30: =D30+E30 -> 9032.26
C31: 4TECH DESENVOLVIMENTO DE SOFTWARES LTDA | D31: 8064.22 | E31: 0 | F31: =D31+E31 -> 8064.22
C32: LUIS EMANUEL RIGON ALDERETE DESENVOLVIMENTO DE SOFTWARE LTDA | D32: 7500 | E32: 0 | F32: =D32+E32 -> 7500
C33: DOUGLAS LIMA MACHADO 02831827094 | D33: 7307 | E33: 0 | F33: =D33+E33 -> 7307 | H33: Tem R$ 7.307 de competência 2025: fica em 2026 (exercício encerrado), é nota explicativa.
C34: DANIEL GERONIMO DO AMARAL 02303012236 | D34: 7200.2 | E34: 0 | F34: =D34+E34 -> 7200.2
C35: 50.836.277 DIEGO ALVES FERREIRA | D35: 4413.95 | E35: 0 | F35: =D35+E35 -> 4413.95
C36: 62.516.834 DAVI GRACIANO NASCIMENTO COSTA | D36: 4000 | E36: 0 | F36: =D36+E36 -> 4000
C37: JMR SOLUCOES DIGITAIS LTDA | D37: 3000 | E37: 0 | F37: =D37+E37 -> 3000
C38: SWILE DO BRASIL S.A. | D38: 2130 | E38: 0 | F38: =D38+E38 -> 2130
C39: Ramon de Sousa Pereira | D39: -1550 | E39: 0 | F39: =D39+E39 -> -1550 | H39: Tem R$ 1.550 de competência 2025: fica em 2026 (exercício encerrado), é nota explicativa.
C40: 55.743.508 JULIANA HELENA VALLE FRASAO | D40: 1129.03 | E40: 0 | F40: =D40+E40 -> 1129.03
A41: 6.2.1.01.003 | B41: Custos com Transações | C41: TOTAL DA CONTA | D41: =SUM(D42:D42) -> 24160.94 | E41: =SUM(E42:E42) -> 59487.01 | F41: =SUM(F42:F42) -> 83647.95
...

Sheet Jun
A1: Junho/2026 — DRE contábil aberto por conta e fornecedor
A2: Cada conta do DRE com os fornecedores do razão (nome como está no livro da Syhus). "Como está" = razão de hoje. "Ajuste" = os lançamentos da aba O QUE FAZER (nº na coluna G). "Como deve ficar" = como a conta fica depois. Os subtotais e totais são fórmulas.
A4: Conta | B4: Descrição | C4: Fornecedor (razão) | D4: Como está | E4: Ajuste | F4: Como deve ficar | G4: Lançamento nº | H4: Observação
A5: 6.2.1.01.001 | B5: Custos com Serviços de Terceiros - Internos | C5: TOTAL DA CONTA | D5: =SUM(D6:D41) -> 390953.79 | E5: =SUM(E6:E41) -> 134097.74 | F5: =SUM(F6:F41) -> 525051.53
C6: DKSWEB DESENVOLVIMENTO DE SOFTWARE LTDA | D6: 0 | E6: 52000 | F6: =D6+E6 -> 52000 | G6: 120, 134
C7: L. A. B. CAMPOS LTDA | D7: 0 | E7: 30000 | F7: =D7+E7 -> 30000 | G7: 119
C8: BEYAUT LTDA | D8: 0 | E8: 22000 | F8: =D8+E8 -> 22000 | G8: 121
C9: LACERDA GUILHERME CONSULTORIA EM TECNOLOGIA DA INFORMACAO LTDA | D9: 0 | E9: 21280 | F9: =D9+E9 -> 21280 | G9: 122
C10: ESPEJOLAB TECNOLOGIA LTDA | D10: 0 | E10: 10000 | F10: =D10+E10 -> 10000 | G10: 137
C11: EDUARDO HENRIQUE KATSURAYAMA ABREU CONSULTORIA EM TECNOLOGIA DA INFORMACAO LTDA | D11: 29032.26 | E11: -9032.26 | F11: =D11+E11 -> 20000 | G11: 118
C12: SAM TECHNOLOGIES LTDA | D12: 0 | E12: 7850 | F12: =D12+E12 -> 7850 | G12: 123
C13: JOAO VICTOR XAVIER DA SILVA 08983862688 | D13: 30933.33 | E13: 0 | F13: =D13+E13 -> 30933.33
C14: THIAGO AUGUSTO DE OLIVEIRA TECNOLOGIA DA INFORMACAO LTDA | D14: 22000 | E14: 0 | F14: =D14+E14 -> 22000
C15: MARCOS THIAGO SILVESTRE DE MORAES CONSULTORIA EM TECNOLOGIA DA INFORMACAO LTDA | D15: 20000 | E15: 0 | F15: =D15+E15 -> 20000
C16: ALEXANDER MAX YOKOGAWA CONSULTORIA EM TECNOLOGIA DA INFORMACAO LTDA | D16: 19000 | E16: 0 | F16: =D16+E16 -> 19000
C17: LEONARDO PIECHA CALDEIRA LTDA | D17: 18700 | E17: 0 | F17: =D17+E17 -> 18700
C18: HIGOR SANTOS DE JESUS LTDA | D18: 16000 | E18: 0 | F18: =D18+E18 -> 16000
C19: 36.256.578 CHRISTIAN RODRIGO CORRALES | D19: 15736.75 | E19: 0 | F19: =D19+E19 -> 15736.75
C20: R R TECNOLOGIA DA INFORMACAO LTDA | D20: 15000 | E20: 0 | F20: =D20+E20 -> 15000
C21: HAGROEX LTDA | D21: 15000 | E21: 0 | F21: =D21+E21 -> 15000
C22: CURRY LABS TECNOLOGIA LTDA | D22: 15000 | E22: 0 | F22: =D22+E22 -> 15000
C23: BAS DIGITAL LTDA | D23: 14000 | E23: 0 | F23: =D23+E23 -> 14000
C24: 54.652.017 JOAO VITOR DE MORAIS ROCHA | D24: 13500 | E24: 0 | F24: =D24+E24 -> 13500
... C41: 02070665 - 005/025 - SWILE DO BRASIL S.A. | D41: 2157.69 | E41: 0 | F41: =D41+E41 -> 2157.69
A42: 6.2.1.01.003 | B42: Custos com Transações | C42: TOTAL DA CONTA | D42: =SUM(D43:D43) -> 24631.6 | E42: =SUM(E43:E43) -> 57078.91 | F42: =SUM(F43:F43) -> 81710.51
C43: PAGAR.ME INSTITUICAO DE PAGAMENTO S.A | D43: 24631.6 | E43: 57078.91 | F43: =D43+E43 -> 81710.51 | G43: 138
A44: 6.2.1.03.001 | B44: Custo de Hospedagem e Infraestrutura (Cloud) | C44: TOTAL DA CONTA | D44: =SUM(D45:D52) -> 281755.1 | E44: =SUM(E45:E52) -> 38558.37 | F44: =SUM(F45:F52) -> 320313.47
C45: AMAZON AWS SERVICOS BRASIL LTDA | D45: 0 | E45: 126682 | F45: =D45+E45 -> 126682 | G45: 129
C46: 944279429428 - 005/026 - AMAZON AWS SERVICOS BRASIL LTDA | D46: 115492.22 | E46: -115492.22 | F46: =D46+E46 -> 0 | G46: 125
C47: GOOGLE CLOUD BRASIL COMPUTACAO E SERVICOS DE DADOS LTDA. | D47: 159918.41 | E47: 27368.59 | F47: =D47+E47 -> 187287 | G47: 133
C48: PADDLE | D48: 2669.8 | E48: 0 | F48: =D48+E48 -> 2669.8
C49: CASTELBRAS DESIGN, COMUNICACAO E TECNOLOGIA DA INFORMACAO LTDA | D49: 2016 | E49: 0 | F49: =D49+E49 -> 2016
C50: WEBSHARE RNW PROXY 42 | D50: 1399.84 | E50: 0 | F50: =D50+E50 -> 1399.84
C51: NT - 001/001 - GODADDY BRASIL | D51: 222.93 | E51: 0 | F51: =D51+E51 -> 222.93
C52: 1043181 - 009/026 - TURBOCLOUD | D52: 35.9 | E52: 0 | F52: =D52+E52 -> 35.9
A53: 6.2.1.03.002 | B53: Custo de Licença de Sofware e Sistemas | C53: TOTAL DA CONTA | D53: =SUM(D54:D77) -> 119226.56 | E53: =SUM(E54:E77) -> 0 | F53: =SUM(F54:F77) -> 119226.56
C54: CARBIGDATA TECNOLOGIA E INTELIGENCIA S/A | D54: 37680 | E54: 0 | F54: =D54+E54 -> 37680
C55: APPCUES | D55: 19025.68 | E55: 0 | F55: =D55+E55 -> 19025.68
C56: POTELO SISTEMAS DE INFORMACAO LTDA | D56: 10000 | E56: 0 | F56: =D56+E56 -> 10000
C57: ANTHROPIC CLAUDE TEAM | D57: 8927.27 | E57: 0 | F57: =D57+E57 -> 8927.27
...

Sheet Notas e pendências
A1: Nota explicativa e pendências da Jusfy — a Syhus não precisa fazer nada aqui
A2: A: a única nota explicativa — competência 2025 que caiu em 2026 (o exercício de 2025 já fechou, então fica em 2026), por fornecedor, pra auditoria e CFO. B: pendências que dependem de resposta da Jusfy (cada uma com o valor e o que falta). C: parece erro, mas o P&L diz que o valor é devido — não mexer sem a Jusfy confirmar.
A4: A. NOTA EXPLICATIVA — Competência 2025 lançada em 2026 (fica em 2026: exercício de 2025 encerrado)
A5: Fornecedor (razão) | B5: Mês | C5: Valor | D5: Conta | E5: Linha do P&L | F5: Explicação
A6: SWILE DO BRASIL S.A. | B6: Jan | C6: 144755 | D6: 4.1.6.01.007 Serviços de Terceiros - Internos | E6: Swile (bônus e benefício) | F6: Bônus de líderes de dez/2025 pago via Swile em jan (NF 1762064). A Controladoria confirmou na rodada anterior que o excesso de jan é bônus, e no gerencial ele está em dez/2025.
A7: DIGESTO PESQUISA E BANCO DE DADOS LTDA | B7: Jan | C7: 138361.9 | D7: 6.2.1.03.003 Custo de APIs de Terceiros | E7: Digesto Pesquisa e Banco de Dados Ltda (Jusbrasil) | F7: Este fornecedor fatura depois do mês de uso (nos outros meses a NF de um mês entra no seguinte). A NF 37368 (R$ 138.362) lançada(s) em jan não correspondem a nenhum mês de 2026: são de dez/2025. Sair da despesa de 2026.
A8: AMAZON AWS SERVICOS BRASIL LTDA | B8: Jan | C8: 107263.42 | D8: 6.2.1.03.001 Custo de Hospedagem e Infraestrutura (Cloud) | E8: Amazon Cloud | F8: Este fornecedor fatura depois do mês de uso (nos outros meses a NF de um mês entra no seguinte). A NF s/nº (R$ 107.263) lançada(s) em jan não correspondem a nenhum mês de 2026: são de dez/2025. Sair da despesa de 2026.
A9: VIR SERVICOS DE INFORMACOES LTDA | B9: Jan | C9: 84888.4 | D9: 6.2.1.03.003 Custo de APIs de Terceiros | E9: Vir Servicos de Informacoes Ltda (Correct Data) | F9: Este fornecedor fatura depois do mês de uso (nos outros meses a NF de um mês entra no seguinte). A NF 6289 (R$ 84.888) lançada(s) em jan não correspondem a nenhum mês de 2026: são de dez/2025. Sair da despesa de 2026.
A10: NOVA DD POSITIVO REPRESENTACOES LTDA. | B10: Jan | C10: 39535.74 | D10: 6.2.1.03.003 Custo de APIs de Terceiros | E10: Nova Dd Positivo Representacoes Ltda. | F10: Este fornecedor fatura depois do mês de uso (nos outros meses a NF de um mês entra no seguinte). A NF 397 (R$ 39.536) lançada(s) em jan não correspondem a nenhum mês de 2026: são de dez/2025. Sair da despesa de 2026.
A11: JULIANO LIMA DA SILVA LTDA | B11: Jan | C11: 30000 | D11: 4.1.6.01.007 Serviços de Terceiros - Internos | E11: Juliano Lima | F11: NF 30 de R$ 30.000 lançada em Jan tem o valor de dez/2025 no ERP (ERP dez/2025 salário); em 2026 o valor é outro. É competência 2025: sai da despesa de 2026 (contra a provisão de 2025).
A12: JUDIT TECNOLOGIA DA INFORMACAO LTDA | B12: Jan | C12: 28491 | D12: 6.2.1.03.003 Custo de APIs de Terceiros | E12: Judit Tecnologia da Informacao Ltda | F12: Este fornecedor fatura depois do mês de uso (nos outros meses a NF de um mês entra no seguinte). A NF 504 (R$ 28.491) lançada(s) em jan não correspondem a nenhum mês de 2026: são de dez/2025. Sair da despesa de 2026.
A13: KARINE C GOMBERG SERVICOS ADMINISTRATIVOS | B13: Jan | C13: 22500 | D13: 4.1.6.01.007 Serviços de Terceiros - Internos | E13: Karine Gomberg | F13: NF 53 de R$ 22.500 entrou em jan, mas o gerencial de jan é outra nota. É competência dez/2025: sai da despesa de 2026 (contra a provisão de 2025).
A14: BRUNO JOSE SOBREIRA CAVALIERI LTDA | B14: Jan | C14: 22000 | D14: 4.1.6.01.007 Serviços de Terceiros - Internos | E14: Bruno José Sobreira Cavalieri | F14: NF 1 de R$ 22.000 lançada em Jan tem o valor de dez/2025 no ERP (ERP dez/2025 salário); em 2026 o valor é outro. É competência 2025: sai da despesa de 2026 (contra a provisão de 2025).
A15: ROCHA CASTANHA SOLUCOES LTDA | B15: Jan | C15: 22000 | D15: 4.1.6.01.007 Serviços de Terceiros - Internos | E15: Clarissa Castanha | F15: NF 202600000000028 de R$ 22.000 lançada em Jan tem o valor de dez/2025 no ERP (ERP dez/2025 salário); em 2026 o valor é outro. É competência 2025: sai da despesa de 2026 (contra a provisão de 2025).
A16: APPCUES | B16: Jan | C16: 20036.07 | D16: 6.2.1.03.002 Custo de Licença de Sofware e Sistemas | E16: Appcues | F16: Este fornecedor fatura depois do mês de uso (nos outros meses a NF de um mês entra no seguinte). A NF s/nº (R$ 20.036) lançada(s) em jan não correspondem a nenhum mês de 2026: são de dez/2025. Sair da despesa de 2026.
A17: BIG DATA SOLUCOES EM TECNOLOGIA DE INFORMATICA S.A. | B17: Jan | C17: 19922.37 | D17: 6.2.1.03.003 Custo de APIs de Terceiros | E17: Big Data Solucoes em Tecnologia de Informatica S.A. | F17: Este fornecedor fatura depois do mês de uso (nos outros meses a NF de um mês entra no seguinte). A NF 152 (R$ 19.922) lançada(s) em jan não correspondem a nenhum mês de 2026: são de dez/2025. Sair da despesa de 2026.
... A244: Mensal - Ramon - s - Ramon de Sousa Pereira | B244: Mai | C244: -15500 | D244: 6.2.1.01.001 Custos com Serviços de Terceiros - Internos | E244: Ramon de Sousa Pereira | F244: Estorno/cancelamento de NF de 01/12/2025 (2025) lançado em Mai/2026, reduzindo a despesa de 2026. É de 2025: lançar contra o resultado de 2025, não contra a despesa de 2026. O gerencial de Mai não tem esse valor.
A245: TOTAL (239 linhas) | C245: 1216735.6
A247: B1a. Google Ads — valor certo por competência (razão = base da Mari); ajustar o P&L
A248: Mês | C248: NFs Google no razão | D248: Base da Mari (ERP, competência) | E248: P&L hoje | F248: Ajuste no P&L (valor certo − P&L)
A249: Janeiro | C249: 507493.95 | D249: 507493.95 | E249: 501335.46 | F249: 6158.49
A250: Fevereiro | C250: 587911.77 | D250: 587911.77 | E250: 587911 | F250: 0.77
A251: Março | C251: 832108.38 | D251: 832108.38 | E251: 812105.21 | F251: 20003.17
A252: Abril | C252: 714588.92 | D252: 714588.92 | E252: 701900.06 | F252: 12688.86
A253: Maio | C253: 1057894.2 | D253: 1057894.2 | E253: 1057894 | F253: 0.17
A254: Junho | C254: 1182057.7 | D254: 1182057.7 | E254: 1177023.6 | F254: 5034.06
A255: TOTAL | C255: 4882054.8 | D255: 4882054.8 | E255: 4838169.3 | F255: 43885.52
A256: Base da Mari: linhas GOOGLE BRASIL / GOOGLE WORKSPACE classificadas em 5.1.1 Aquisição Digital (ADS), somadas por competência (todas as contas da Google: SaaS, Jusmatch, Enterprise, Internacional). Em jan, a NF 35933274 (R$ 9.349,64) está no ERP como "GOOGLE WORKSPACE", classe ADS.
A258: B1b. Imposto retido — o razão lança o valor bruto da NF; o ERP (e o P&L) tem o líquido pago
A259: Fornecedor (razão) | B259: Mês | C259: Diferença no mês | D259: NF (razão) → pago (ERP) | E259: Retido | F259: O que decidir
A260: RECH & LONGO LTDA | B260: Jan | C260: 149 | D260: NF 31 9.916 → 9.767 | E260: 149 (1,50%) | F260: Contábil está certo (despesa = valor bruto da NF). O P&L usa o valor pago ao fornecedor. Decidir: P&L passa a usar o bruto, ou o retido entra na linha de impostos.
A261: CARBIGDATA TECNOLOGIA E INTELIGENCIA S/A | B261: Fev | C261: 730 | D261: NF 2725 11.868 → 11.138 | E261: 730 (6,15%) | F261: Contábil está certo (despesa = valor bruto da NF). O P&L usa o valor pago ao fornecedor. Decidir: P&L passa a usar o bruto, ou o retido entra na linha de impostos.
A262: RECH & LONGO LTDA | B262: Fev | C262: 149 | D262: NF 58 9.916 → 9.767 | E262: 149 (1,50%) | F262: Contábil está certo (despesa = valor bruto da NF). O P&L usa o valor pago ao fornecedor. Decidir: P&L passa a usar o bruto, ou o retido entra na linha de impostos.
